<?xml version="1.0"?>
<robot name="magneticbot">
  <link name="base_link">
    <visual>
      <geometry>
        <cylinder length="0.3" radius="0.25"/>
      </geometry>
      <material name="silver">
        <color rgba="0.75 0.75 0.75 1.0"/>
      </material>
    </visual>
    <collision>
      <geometry>
        <cylinder length="0.3" radius="0.25"/>
      </geometry>
    </collision>
    <inertial>
      <mass value="1.0"/>
      <inertia ixx="0.023125" iyy="0.023125" izz="0.03125"
               ixy="0.0" ixz="0.0" iyz="0.0"/>
    </inertial>
  </link>
  
  <!-- urdf doesn't support the ball joint type which is supported by sdf, 
       so we have to use a cylinder wheel plus a front caster to simulate  
       a sphere caster wheel. -->
  <link name="front_caster">
    <visual>
      <geometry>
        <box size="0.07 0.1 0.3"/>
      </geometry>
      <material name="silver"/>
    </visual>
    <collision>
      <geometry>
        <box size="0.07 0.1 0.3"/>
      </geometry>
    </collision>
    <inertial>
      <mass value="0.1"/>
      <inertia ixx="8.3333e-4" iyy="7.9083e-4" izz="1.2417e-4"
               ixy="0.0" ixz="0.0" iyz="0.0"/>
    </inertial>
  </link>
  
  <joint name="front_caster_joint" type="continuous">
    <axis xyz="0.0 0.0 1.0"/>
    <parent link="base_link"/>
    <child link="front_caster"/>
    <origin rpy="0 0 0" xyz="0.25 0.0 0.0"/>
  </joint>
       
  <link name="front_wheel">
    <visual>
      <geometry>
        <cylinder length="0.05" radius="0.035"/>
        <material name="black">
          <color rgba="0.0 0.0 0.0 1.0"/>
        </material>
      </geometry>
    </visual>
    <collision>
      <geometry>
        <cylinder length="0.05" radius="0.035"/>
      </geometry>
    </collision>
    <inertial>
      <mass value="0.1"/>
      <inertia ixx="5.1458e-5" iyy="5.1458e-5" izz="6.125e-5"
               ixy="0.0" ixz="0.0" iyz="0.0"/>
    </inertial>
  </link>
  
  <joint name="front_wheel_joint" type="continuous">
    <axis xyz="0.0 0.0 1.0"/>
    <parent link="front_caster"/>
    <child link="front_wheel"/>
    <origin rpy="-1.5708 0.0 0.0" xyz="0.035 0.0 -0.15"/>
  </joint>
  
  <link name="left_rear_wheel">
    <visual>
      <geometry>
        <cylinder length="0.05" radius="0.035"/>
        <material name="black"/>
      </geometry>
    </visual>
    <collision>
      <geometry>
        <cylinder length="0.05" radius="0.035"/>
      </geometry>
    </collision>
    <inertial>
      <mass value="0.1"/>
      <inertia ixx="5.1458e-5" iyy="5.1458e-5" izz="6.125e-5"
               ixy="0.0" ixz="0.0" iyz="0.0"/>
    </inertial>  
  </link>
  
  <joint name="left_rear_wheel_joint" type="continuous">
    <axis xyz="0.0 0.0 1.0"/>
    <parent link="base_link"/>
    <child link="left_rear_wheel"/>
    <origin rpy="-1.5708 0.0 0.0" xyz="-0.175 0.175 -0.15"/>  
  </joint>
  
  <link name="right_rear_wheel">
    <visual>
      <geometry>
        <cylinder length="0.05" radius="0.035"/>
        <material name="black"/>
      </geometry>
    </visual>
    <collision>
      <geometry>
        <cylinder length="0.05" radius="0.035"/>
      </geometry>
    </collision>
    <inertial>
      <mass value="0.1"/>
      <inertia ixx="5.1458e-5" iyy="5.1458e-5" izz="6.125e-5"
               ixy="0.0" ixz="0.0" iyz="0.0"/>
    </inertial>  
  </link>
  
  <joint name="right_rear_wheel_joint" type="continuous">
    <axis xyz="0.0 0.0 1.0"/>
    <parent link="base_link"/>
    <child link="right_rear_wheel"/>
    <origin rpy="-1.5708 0.0 0.0" xyz="-0.175 -0.175 -0.15"/>  
  </joint>
  
  <link name="laser_link">
    <visual>
      <geometry>
        <box size="0.1 0.1 0.1"/>
      </geometry>
      <material name="silver"/>
    </visual>
    <collision>
      <geometry>
        <box size="0.1 0.1 0.1"/>
      </geometry>
    </collision>
    <inertial>
      <mass value="0.05"/>
      <origin xyz="0.0 0.0 0.0" rpy="0.0 0.0 0.0"/>
      <inertia ixx="8.3333e-5" iyy="8.3333e-5" izz="8.3333e-5" 
               ixy="0.0" ixz="0.0" iyz="0.0"/>
    </inertial>
  </link>
  
  <joint name="laser_joint" type="fixed">
    <parent link="base_link"/>
    <child link="laser_link"/>
    <origin rpy="0.0 0.0 0.0" xyz="0.0 0.0 0.20"/>
  </joint>
  
  <gazebo>
    <plugin name="differential_drive_controller" filename="libgazebo_ros_diff_drive.so">
      <leftJoint>left_rear_wheel_joint</leftJoint>
      <rightJoint>right_rear_wheel_joint</rightJoint>
      <robotBaseFrame>base_link</robotBaseFrame>
      <wheelSeparation>0.35</wheelSeparation>
      <wheelDiameter>0.07</wheelDiameter>
      <wheelTorque>5.0</wheelTorque>
      <publishWheelJointState>true</publishWheelJointState>
      <legacyMode>false</legacyMode>
    </plugin>
  </gazebo>
    
  <gazebo>  
    <plugin name="joint_state_publisher" filename="libgazebo_ros_joint_state_publisher.so">
      <jointName>front_caster_joint, front_wheel_joint</jointName>
    </plugin>
  </gazebo>
  
  <!-- The LiDAR parameters are taken from the data sheet of SLAMTEC's A2M6. -->
  <gazebo reference="laser_link">
    <sensor type="ray" name="laser">
      <pose>0.0 0.0 0.0 0.0 0.0 0.0</pose>
      <visualize>false</visualize>
      <update_rate>10</update_rate> <!-- scan rate -->
      <ray>
        <scan>
          <horizontal>
            <samples>400</samples>  <!-- number of samples on one scan circumference -->
            <resolution>1</resolution>
            <min_angle>-3.1415926</min_angle>  <!-- one scan from -pi to pi -->
            <max_angle>3.1415926</max_angle>
          </horizontal>
        </scan>
        <range>
          <min>0.2</min>
          <max>16.0</max>
          <resolution>0.005</resolution>
        </range>
      </ray>
      <plugin name="laser" filename="libgazebo_ros_laser.so">
        <topicName>/scan</topicName>
        <frameName>laser_link</frameName>
      </plugin>
    </sensor>
  </gazebo>
</robot>
